
Sanity Checking: 0it [00:00, ?it/s]
GPU available: False, used: False
TPU available: False, using: 0 TPU cores
IPU available: False, using: 0 IPUs
HPU available: False, using: 0 HPUs
  | Name          | Type          | Params
------------------------------------------------
0 | generator     | Generator     | 575
1 | discriminator | Discriminator | 89
------------------------------------------------
664       Trainable params
0         Non-trainable params
664       Total params


Epoch 0:  79%|██████████████████████████▋       | 11/14 [00:04<00:01,  2.38it/s, v_num=jv8v, train_generator_loss_step=0.962, train_discriminator_loss_step=1.100]
Validation: 0it [00:00, ?it/s]
/opt/homebrew/Caskroom/miniconda/base/envs/datascience/lib/python3.9/site-packages/pytorch_lightning/trainer/call.py:48: UserWarning: Detected KeyboardInterrupt, attempting graceful shutdown...
  rank_zero_warn("Detected KeyboardInterrupt, attempting graceful shutdown...")
Traceback (most recent call last):
  File "/Users/nehcream/Documents/Workspace/Active/AI-SPARK-Challenge/train.py", line 147, in <module>
    main(config)
  File "/Users/nehcream/Documents/Workspace/Active/AI-SPARK-Challenge/train.py", line 107, in main
    result = trainer.validate(model, val_dataloaders=val_loader)
TypeError: validate() got an unexpected keyword argument 'val_dataloaders'